Workbook
Name _: '[1]충돌 내용'!#REF!
Name _: '[1]충돌 내용'!#REF!
Name _: '[1]충돌 내용'!#REF!
Name __DAN100: #REF!
Name __DAN103: #REF!
Name __DAN104: #REF!
Name __DAN107: #REF!
Name __DAN108: #REF!
Name __DAN109: #REF!
Name __DAN11: #REF!
Name __DAN110: #REF!
Name __DAN111: #REF!
Name __DAN112: #REF!
Name __DAN113: #REF!
Name __DAN114: #REF!
Name __DAN115: #REF!
Name __DAN116: #REF!
Name __DAN117: #REF!
Name __DAN118: #REF!
Name __DAN119: #REF!
Name __DAN12: #REF!
Name __DAN120: #REF!
Name __DAN121: #REF!
Name __DAN122: #REF!
Name __DAN123: #REF!
Name __DAN124: #REF!
Name __DAN125: #REF!
Name __DAN126: #REF!
Name __DAN127: #REF!
Name __DAN128: #REF!
Name __DAN129: #REF!
Name __DAN13: #REF!
Name __DAN130: #REF!
Name __DAN131: #REF!
Name __DAN132: #REF!
Name __DAN133: #REF!
Name __DAN134: #REF!
Name __DAN135: #REF!
Name __DAN136: #REF!
Name __DAN137: #REF!
Name __DAN138: #REF!
Name __DAN139: #REF!
Name __DAN14: #REF!
Name __DAN140: #REF!
Name __DAN141: #REF!
Name __DAN142: #REF!
Name __DAN143: #REF!
Name __DAN144: #REF!
Name __DAN145: #REF!
Name __DAN146: #REF!
Name __DAN147: #REF!
Name __DAN148: #REF!
Name __DAN149: #REF!
Name __DAN15: #REF!
Name __DAN150: #REF!
Name __DAN151: #REF!
Name __DAN152: #REF!
Name __DAN153: #REF!
Name __DAN16: #REF!
Name __DAN17: #REF!

Sheet 수량산출서 (2)
A1: ='표지 '!A5:M5 -> 순천 향교 CCTV 구매 설치 | F1: 지중 | S1: 임의 | T1: 임의
A2: 연번 | B2: 품 명 | C2: 규 격 | D2: 단위 | E2: 수량 | F2: 방범 | R2: 차량번호인식 | U2: 교체 | V2: 비고
F3: 1.연향동 세영아파트 인근, 순천서림교회와 팔마3길40 건물 사이 삼거리 | G3: 2.서면 지본리 390-2, 버스승강장 부근 삼거리 | H3: 3.승주읍 무학길 46, 무학마을 | I3: 4.환선로 52-1, 만수경로당 | J3: 5.황전면 죽내리 290-1, 봉성마을 입구 | K3: 6.황전면 비촌리 1067-1, 비촌마을 | L3: 7.승주읍 서평리 72-1, 와촌식당 앞 | M3: 8.조례동 1531-15, 조례사거리 | N3: 9.해룡면 선학리 998, 계당마을 입구 | O3: 10.연향상가8길 23, 빽다방 뒤쪽 | P3: 12.장선배기길 189, 금당중 옆 | Q3: 15.덕월동 465, 삼거리 | R3: 16.이수로 291, 순천우리병원 삼거리 | S3: 17.백강로 93, 순천동부주유소 삼거리 | T3: 18.복성리 464-3, 복성고 삼거리 | U3: 20.서면 압곡리 591-6, 순천IC
B4: 공사 유형(신규, 추가) | F4: 신규 | G4: 신규 | H4: 신규 | I4: 신규 | J4: 신규 | K4: 신규 | L4: 신규 | M4: 신규 | N4: 신규 | O4: 신규 | P4: 신규 | Q4: 신규 | R4: 신규 | S4: 신규 | T4: 신규 | U4: 교체
B5: 카메라 유형 | C5: 합계 | D5: EA | E5: =SUM(E6:E8) -> 39 | F5: =SUM(F6:F8) -> 2 | G5: =SUM(G6:G8) -> 3 | H5: =SUM(H6:H8) -> 2 | I5: =SUM(I6:I8) -> 2 | J5: =SUM(J6:J8) -> 2 | K5: =SUM(K6:K8) -> 3 | L5: =SUM(L6:L8) -> 3 | ... U5: =SUM(U6:U8) -> 2
C6: 고정 | D6: EA | E6: =SUM(F6:U6) -> 20 | F6: 1 | H6: 2 | I6: 2 | J6: 1 | K6: 2 | L6: 2 | M6: 2 | N6: 2 | O6: 2 | P6: 2 | Q6: 2
C7: 회전 | D7: EA | E7: =SUM(F7:U7) -> 11 | F7: 1 | G7: 1 | J7: 1 | K7: 1 | L7: 1 | M7: 2 | N7: 1 | O7: 1 | P7: 1 | Q7: 1
C8: 고정(차량번호인식용) | D8: EA | E8: =SUM(F8:U8) -> 8 | G8: 2 | R8: 2 | S8: 1 | T8: 1 | U8: 2
B9: 지지대 유형 | D9: 구분 | E9: =SUM(E10:E13) -> 16 | F9: 폴 | G9: 폴(차량용) | H9: 전주 | I9: 폴 | J9: 전주 | K9: 전주 | L9: 전주 | M9: 전주,신호등 | N9: 전주 | O9: 전주 | P9: 폴 | Q9: 전주 | R9: 폴(차량용) | S9: 폴(차량용) | T9: 폴(차량용)
D10: 전주 | E10: =SUM(F10:U10) -> 8 | H10: 1 | J10: 1 | K10: 1 | L10: 1 | M10: 1 | N10: 1 | O10: 1 | Q10: 1
D11: 폴 | E11: =SUM(F11:U11) -> 3 | F11: 1 | I11: 1 | P11: 1
D12: 폴(차량) | E12: =SUM(F12:U12) -> 4 | G12: 1 | R12: 1 | S12: 1 | T12: 1
D13: 신호등 | E13: =SUM(F13:U13) -> 1 | M13: 1
B14: 전주 사용 시 사용 전주 갯수 | D14: EA | E14: =SUM(F14:U14) -> 9 | H14: 1 | J14: 1 | K14: 1 | L14: 1 | M14: 2 | N14: 1 | O14: 1 | Q14: 1
B15: 지중화작업구간 | D15: EA | E15: =SUM(F15:U15) -> 1 | F15: 1
A16: 1 | B16: =A1&"[도급공사]" -> 순천 향교 CCTV 구매 설치[도급공사] | D16: 식 | E16: 1
A17: 1-1 | B17: 멀티콘센트 | C17: 접지5구 | D17: EA | E17: =SUM(F17:U17) -> 15 | F17: 1 | G17: 1 | H17: 1 | I17: 1 | J17: 1 | K17: 1 | L17: 1 | M17: 1 | N17: 1 | O17: 1 | P17: 1 | Q17: 1 | R17: 1 | S17: 1 | T17: 1
A18: 1-2 | B18: 노출콘센트 | C18: 접지2구 | D18: EA | E18: =SUM(F18:U18) -> 15 | F18: 1 | G18: 1 | H18: 1 | I18: 1 | J18: 1 | K18: 1 | L18: 1 | M18: 1 | N18: 1 | O18: 1 | P18: 1 | Q18: 1 | R18: 1 | S18: 1 | T18: 1
A19: 1-3 | B19: 계량기함 | C19: 소형전자식 | D19: EA | E19: =SUM(F19:U19) -> 15 | F19: 1 | G19: 1 | H19: 1 | I19: 1 | J19: 1 | K19: 1 | L19: 1 | M19: 1 | N19: 1 | O19: 1 | P19: 1 | Q19: 1 | R19: 1 | S19: 1 | T19: 1
A20: 1-4 | B20: 암대 | C20: ARM 1.5m | D20: EA | E20: =SUM(F20:U20) -> 9 | H20: 1 | J20: 1 | K20: 1 | L20: 1 | M20: 2 | N20: 1 | O20: 1 | Q20: 1
A21: 1-5 | B21: UTP케이블 | C21: CAT6 4P | D21: M | E21: =SUM(F21:U21) -> 390 | F21: 20 | G21: 30 | H21: 20 | I21: 20 | J21: 20 | K21: 30 | L21: 30 | M21: 40 | N21: 30 | O21: 30 | P21: 30 | Q21: 30 | R21: 20 | S21: 10 | T21: 10 | U21: 20
A22: 1-6 | B22: 제어케이블(카메라전원) | C22: VCTF 1.5㎟ 2C | D22: M | E22: =SUM(F22:U22) -> 210 | F22: 10 | G22: 30 | J22: 10 | K22: 10 | L22: 10 | M22: 40 | N22: 10 | O22: 10 | P22: 10 | Q22: 10 | R22: 20 | S22: 10 | T22: 10 | U22: 20
A23: 1-7 | B23: 난연전력케이블(메인전원) | C23: F-CV 4㎟ 2C | D23: M | E23: =SUM(F23:U23) -> 210 | F23: 15 | G23: 15 | H23: 15 | I23: 15 | J23: 15 | K23: 15 | L23: 15 | M23: 15 | N23: 15 | O23: 15 | P23: 15 | Q23: 15 | R23: 10 | S23: 10 | T23: 10
A24: 1-8 | B24: 누전차단기 | C24: 2P30AF, 분전반용 | D24: EA | E24: =SUM(F24:U24) -> 15 | F24: 1 | G24: 1 | H24: 1 | I24: 1 | J24: 1 | K24: 1 | L24: 1 | M24: 1 | N24: 1 | O24: 1 | P24: 1 | Q24: 1 | R24: 1 | S24: 1 | T24: 1
A25: 1-9 | B25: 스위치허브 | C25: 4 PORT | D25: EA | E25: =SUM(F25:U25) -> 11 | F25: 1 | H25: 1 | I25: 1 | J25: 1 | K25: 1 | L25: 1 | M25: 1 | N25: 1 | O25: 1 | P25: 1 | Q25: 1
A27: 2 | B27: =A1&"[관급자재]" -> 순천 향교 CCTV 구매 설치[관급자재] | D27: 식 | E27: 1 | V27: 물품식별번호
A28: 2-1 | B28: 라이센스 차량번호인식용 | C28: 문제차량 | D28: 조 | E28: =SUM(F28:U28) -> 2 | U28: 2 | V28: =단가조사!#REF! -> #REF!
A29: 2-2 | B29: 고정카메라 | C29: 200만화소 이상 | D29: 조 | E29: =SUM(F29:U29) -> 20 | F29: 1 | H29: 2 | I29: 2 | J29: 1 | K29: 2 | L29: 2 | M29: 2 | N29: 2 | O29: 2 | P29: 2 | Q29: 2 | V29: =단가조사!#REF! -> #REF!
A30: 2-3 | B30: 회전카메라 | C30: 200만화소 이상, 25배줌이상, 자동줌 | D30: 조 | E30: =SUM(F30:U30) -> 11 | F30: 1 | G30: 1 | J30: 1 | K30: 1 | L30: 1 | M30: 2 | N30: 1 | O30: 1 | P30: 1 | Q30: 1 | V30: =단가조사!#REF! -> #REF!
A31: 2-4 | B31: 방범식별카메라(차량번호인식용) | C31: 200만화소 이상 | D31: 조 | E31: =SUM(F31:U31) -> 6 | G31: 2 | R31: 2 | S31: 1 | T31: 1 | V31: =단가조사!#REF! -> #REF!
A32: 2-5 | B32: 방범추출카메라(차량번호인식용) | C32: 200만화소 이상 | D32: 조 | E32: =SUM(F32:U32) -> 2 | U32: 2 | V32: =단가조사!#REF! -> #REF!
A33: 2-6 | B33: POLE | C33: Φ152.4mm×6m×2mm | D33: EA | E33: =SUM(F33:U33) -> 3 | F33: 1 | I33: 1 | P33: 1 | V33: =단가조사!#REF! -> #REF!
A34: 2-7 | B34: POLE(차량번호인식용) | C34: Φ267mm×8m×6mm | D34: EA | E34: =SUM(F34:U34) -> 4 | G34: 1 | R34: 1 | S34: 1 | T34: 1 | V34: =단가조사!#REF! -> #REF!
A35: 2-8 | B35: 함체 | C35: 300*400*300mm | D35: EA | E35: =SUM(F35:U35) -> 15 | F35: 1 | G35: 1 | H35: 1 | I35: 1 | J35: 1 | K35: 1 | L35: 1 | M35: 1 | N35: 1 | O35: 1 | P35: 1 | Q35: 1 | R35: 1 | S35: 1 | T35: 1 | V35: =단가조사!#REF! -> #REF!
A36: 2-9 | B36: 안내판 | C36: CCTV 안내판(중) | D36: 개 | E36: =SUM(F36:U36) -> 16 | F36: 1 | G36: 1 | H36: 1 | I36: 1 | J36: 1 | K36: 1 | L36: 1 | M36: 2 | N36: 1 | O36: 1 | P36: 1 | Q36: 1 | R36: 1 | S36: 1 | T36: 1 | V36: =단가조사!#REF! -> #REF!
A37: 2-10 | B37: 고정카메라 브래킷 | C37: 고정카메라 부착 | D37: 개 | E37: =SUM(F37:U37) -> 28 | F37: 1 | G37: 2 | H37: 2 | I37: 2 | J37: 1 | K37: 2 | L37: 2 | M37: 2 | N37: 2 | O37: 2 | P37: 2 | Q37: 2 | R37: 2 | S37: 1 | T37: 1 | U37: 2 | V37: =단가조사!#REF! -> #REF!
A38: 2-11 | B38: 회전카메라 브래킷 | C38: 회전카메라 부착 | D38: 개 | E38: =SUM(F38:U38) -> 11 | F38: 1 | G38: 1 | J38: 1 | K38: 1 | L38: 1 | M38: 2 | N38: 1 | O38: 1 | P38: 1 | Q38: 1 | V38: =단가조사!#REF! -> #REF!
A39: 2-12 | B39: 시험 | C39: 종합시험 | D39: 식 | E39: =SUM(F39:U39) -> 16 | F39: 1 | G39: 1 | H39: 1 | I39: 1 | J39: 1 | K39: 1 | L39: 1 | M39: 1 | N39: 1 | O39: 1 | P39: 1 | Q39: 1 | R39: 1 | S39: 1 | T39: 1 | U39: 1 | V39: =단가조사!#REF! -> #REF!
A40: 2-13 | B40: 난연접지용 비닐절연전선 | C40: F-GV 6㎟ | D40: M | E40: =SUM(F40:U40) -> 75 | F40: 5 | G40: 5 | H40: 5 | I40: 5 | J40: 5 | K40: 5 | L40: 5 | M40: 5 | N40: 5 | O40: 5 | P40: 5 | Q40: 5 | R40: 5 | S40: 5 | T40: 5 | V40: =단가조사!#REF! -> #REF!
A41: 2-14 | B41: 접지봉 | C41: 14mm * 1m | D41: 개 | E41: =SUM(F41:U41) -> 45 | F41: 3 | G41: 3 | H41: 3 | I41: 3 | J41: 3 | K41: 3 | L41: 3 | M41: 3 | N41: 3 | O41: 3 | P41: 3 | Q41: 3 | R41: 3 | S41: 3 | T41: 3 | V41: =단가조사!#REF! -> #REF!
...

Sheet 표지 
A5: 순천 향교 CCTV 구매 설치
A10: 2026. 7.
A18: 순 천 시

Sheet 설계설명서
A1: 설 계 설 명 서
B3: ❍ | C3: 공 사 명 : 순천 향교 CCTV 구매 설치
B4: ❍ | C4: 목 적 : 순천 향교 내에 CCTV를 설치하여 돌발 및 안전사고를 예방하고 시설물 보호를 위함
B5: ❍ | C5: 위 치 : 순천 향교 내 4개소
B6: ❍ | C6: 공사내용
B7: - | C7: 총 사업량 : 4개소 6대 (고정형 6대)
B8: ❍ | C8: 예정공정표
C9: 일 정 공정별 | D9: 착공일로부터 60일 간
D10: 1~5일 | E10: 6-15일 | F10: 16~50일 | G10: 51~55일 | H10: 56-60일
C11: 1. 착수 및 자재 검토
C12: 2. 현장조사 및 자재 준비
C13: 3. 카메라, 시스템 설치
C14: 4. 센터 연계, 시운전 및 종합 시험
C15: 5. 교육 및 인수인계, 완료

Sheet 설계표지
A1: 과 장 | B1: 설계년월일 | C1: 2026년 7월 일 | G1: 주소 : 전남 순천시 향교길 60 순천향교
B2: 심사년월일 | C2: 2026년 7월 일
A5: 팀 장 | B5: ='표지 '!A5 -> 순천 향교 CCTV 구매 설치
B8: ▨ 공 사 개 요
A9: 심 사 자 | B9: ="1. "&B5&" [관급자재] --- 1 식" -> 1. 순천 향교 CCTV 구매 설치 [관급자재] --- 1 식
A13: 설 계 자
B14: ="▨ 총 액 : 금"&NUMBERSTRING(원가!D26,1)&"원(금"&TEXT(원가!D26,"#,###원)") -> ▨ 총 액 : 금이천이십팔만사천원(금20,284,000원)
B15: =" - 관급자재 : 금"&NUMBERSTRING(원가!D25,1)&"원(금"&TEXT(원가!D25,"#,###원)") -> - 관급자재 : 금이천이십팔만사천원(금20,284,000원)
A17: 조 사 자
B18: ='표지 '!A18 -> 순 천 시

Sheet 원가
A1: 원 가 계 산 서
A3: ='표지 '!A5:M5 -> 순천 향교 CCTV 구매 설치
A4: 비 목 | C4: 구 분 | D4: 금 액 | E4: 구 성 비 | F4: 반영요율 | G4: 제비율 기준 | H4: 수량 | I4: 금액
B5: 재 | C5: 직 접 재 료 비 | D5: =도급집계표!G4 -> 0 | H5: 1 | I5: =D5*H5 -> 0
B6: 료 | C6: 간 접 재 료 비 | I6: =D6*H6 -> 0
B7: 비 | C7: ( 소 계 ) | D7: =SUM(D5:D6) -> 0 | I7: =D7*H7 -> 0
A8: 순 | B8: 노 | C8: 직 접 노 무 비 | D8: =도급집계표!I4 -> 0 | H8: 1 | I8: =D8*H8 -> 0
B9: 무 | C9: 간 접 노 무 비 | D9: =TRUNC((D8)*F9/100) -> 0 | E9: (직접 노무비) * | F9: 15 | G9: 15.0% | H9: 1 | I9: =D9*H9 -> 0
B10: 비 | C10: ( 소 계 ) | D10: =SUM(D8:D9) -> 0 | I10: =D10*H10 -> 0
A11: 공 | C11: 기 계 경 비 | H11: 1 | I11: =D11*H11 -> 0
C12: 산 재 보 험 료 | D12: =TRUNC((D10)*F12/100) -> 0 | E12: (노무비) * | F12: 3.56 | G12: 3.56% | H12: 1 | I12: =D12*H12 -> 0
B13: 경 | C13: 고 용 보 험 료 | D13: =TRUNC((D10)*F13/100) -> 0 | E13: (노무비) * | F13: 1.01 | G13: 1.01% | H13: 1 | I13: =D13*H13 -> 0
A14: 사 | C14: 기 타 경 비 | D14: =TRUNC((D7+D10)*F14%) -> 0 | E14: (재료+노무) * | F14: 4.6 | G14: 4.6% | H14: 1 | I14: =D14*H14 -> 0
C15: 건 강 보 험 료 | D15: =TRUNC((D8)*F15/100) -> 0 | E15: (직접 노무비) * | F15: 3.595 | G15: 3.595% | H15: 1 | I15: =D15*H15 -> 0
B16: 비 | C16: 연 금 보 험 료 | D16: =TRUNC((D8)*F16/100) -> 0 | E16: (직접 노무비) * | F16: 4.75 | G16: 4.75% | H16: 1 | I16: =D16*H16 -> 0
A17: 비 | C17: 노인장기요양보험 | D17: =TRUNC((D15)*F17/100) -> 0 | E17: (건강 보험료) * | F17: 13.14 | G17: 13.14% | H17: 1 | I17: =D17*H17 -> 0
C18: 산업안전보건관리비 | D18: =TRUNC((D7+D8)*F18%) -> 0 | E18: (재료+직접노무비) * | F18: 3.11 | G18: 3.11% | H18: 1
C19: ( 소 계 ) | D19: =SUM(D11:D17) -> 0
B20: ( 순공사비 계 ) | D20: =D7+D10+D19 -> 0 | I20: =D20*H20 -> 0
A21: 일 반 관 리 비 | D21: =TRUNC((D7+D10+D19)*F21%) -> 0 | E21: (재료+노무+경비) * 6 % | F21: 8 | G21: 8% | H21: 1 | I21: =D21*H21 -> 0
A22: 이 윤 | D22: =TRUNC((D10+D19+D21)*F22%) -> 0 | E22: (노무+경비+일반관리비) *15% | F22: 15 | G22: 15% | H22: 1 | I22: =D22*H22 -> 0
A23: ( 총 원 가 ) | D23: =TRUNC((D20+D21+D22),-4) -> 0 | E23: 천단위절사 | I23: =D23*H23 -> 0
A24: 부 가 가 치 세 | D24: =TRUNC((D23)*F24%) -> 0 | E24: 10% | F24: 10 | H24: 1 | I24: =D24*H24 -> 0
A25: 관급자재 | D25: =관급집계표!K23 -> 20284000 | I25: =D25*H25 -> 0
A26: ( 총 계 ) | D26: =SUM(D25:D25) -> 20284000
D30: =#REF!*5% -> #REF! | E30: 도급 95% 계약 시 삭감 예상액

Sheet 도급집계표
A1: ='표지 '!A5:M5 -> 순천 향교 CCTV 구매 설치 | L1: [ 도 급 집 계 표 ]
B2: 명 칭 | C2: 규 격 | D2: 단위 | E2: 수량 | F2: 재 료 비 | H2: 노 무 비 | J2: 경 비 | L2: 계 | M2: 비 고
F3: 단가 | G3: 금액 | H3: 단가 | I3: 금액 | J3: 단가 | K3: 금액
A4: =도급내역서!A4 -> #REF! | B4: =도급내역서!B4 -> #REF! | D4: 식 | E4: 1 | G4: =도급내역서!G22 -> 0 | I4: =도급내역서!I22 -> 0 | L4: =TRUNC(SUM(G4+I4)) -> 0
B19: 합 계 | L19: =L4 -> 0

Sheet 도급내역서
A1: ='표지 '!A5:M5 -> 순천 향교 CCTV 구매 설치 | L1: [ 도 급 내 역 서 ]
B2: 명 칭 | C2: 규 격 | D2: 수량 | E2: 단위 | F2: 재료비 | H2: 노무비 | J2: 경 비 | L2: 계 | M2: 비고
F3: 단가 | G3: 금액 | H3: 단가 | I3: 금액 | J3: 단가 | K3: 금액
A4: =수량산출서!#REF! -> #REF! | B4: =수량산출서!#REF! -> #REF!
M5: 현장설치도
M6: 제 1호표
M7: 제 2호표
M8: 제 3호표
B22: 소 계 | G22: =SUM(G5:G21) -> 0 | I22: =SUM(I5:I21) -> 0 | L22: =SUM(L5:L21) -> 0

Sheet 도급일위대가표
A1: ='표지 '!A5:M5 -> 순천 향교 CCTV 구매 설치 | N1: [ 도 급 일 위 대 가 표 ]
A2: 품 명 | C2: 규 격 | D2: 단 위 | E2: 공 량 | F2: 할증 % | G2: 재 료 비 | I2: 노 무 비 | K2: 경 비 | M2: 합 계 | O2: 비 고
G3: 단가 | H3: 금 액 | I3: 단가 | J3: 금 액 | K3: 단가 | L3: 금 액 | M3: 단가 | N3: 금액
A4: 제 1 호표
A5: =도급내역서!B6 -> 0 | C5: =도급내역서!C6 -> 0 | D5: =도급내역서!E6 -> 0 | E5: 1
B6: 포설 | C6: 통신케이블공 | D6: 인 | E6: 0.012 | F6: 100 | I6: =노임단가!I31 -> 389536 | J6: =TRUNC(I6*E6*F6%) -> 4674 | N6: =SUM(H6,J6,L6) -> 4674 | O6: 통신표품 4-4-1 제어용 케이블 적용
B7: 소 계 | J7: =TRUNC(SUM(J6:J6)) -> 4674 | N7: =SUM(N6:N6) -> 4674
A8: 제 2 호표
A9: =도급내역서!B7 -> 0 | C9: =도급내역서!C7 -> 0 | D9: =도급내역서!E7 -> 0 | E9: 1
B10: 포설 | C10: 통신케이블공 | D10: 인 | E10: 0.015 | F10: 100 | I10: =노임단가!I31 -> 389536 | J10: =TRUNC(I10*E10*F10%) -> 5843 | N10: =SUM(H10,J10,L10) -> 5843 | O10: 통신표품 4-3-1 꼬임케이블 적용 | Q10: 0.015 | R10: =Q10*180% -> 0.027
B11: 소 계 | J11: =TRUNC(SUM(J10:J10)) -> 5843 | N11: =TRUNC(SUM(N10:N10)) -> 5843
A12: 제 3 호표
A13: =도급내역서!B8 -> 0 | C13: =도급내역서!C8 -> 0 | D13: =도급내역서!E8 -> 0 | E13: 1
B14: 포설 | C14: 통신케이블공 | D14: 인 | E14: 0.016 | F14: 100 | I14: =노임단가!I31 -> 389536 | J14: =TRUNC(I14*E14*F14%) -> 6232 | N14: =SUM(H14,J14,L14) -> 6232 | O14: 통신표품 4-4-1 제어용 케이블 적용
B15: 소 계 | J15: =TRUNC(SUM(J14:J14)) -> 6232 | N15: =TRUNC(SUM(N14:N14)) -> 6232

Sheet 표준품셈

Sheet 노임단가
A1: 2023년 상반기 적용 정보통신부문 시중노임단가(2023.1.1 ~ )
A3: 공 표 일 | C3: 2023.01.01 | D3: 공 표 일 | F3: 2023.01.01 | G3: 공 표 일 | I3: 2023.01.01 | J3: 공 표 일 | L3: 2023.01.01
A4: 번 호 직 종 명 | D4: 번 호 직 종 명 | G4: 번 호 직 종 명 | J4: 번 호 직 종 명
A5: 1001 | B5: 작업반장 | C5: 197546 | D5: **1032 | E5: 연마공 | F5: - | G5: *1063 | H5: 플랜트계장공 | I5: 215631 | J5: *3001 | K5: 도편수 | L5: 457143
A6: 1002 | B6: 보통인부 | C6: 157068 | D6: 1033 | E6: 석공 | F6: 245307 | G6: **1064 | H6: 플랜트덕트공 | I6: - | J6: **3002 | K6: 드잡이공 | L6: -
A7: 1003 | B7: 특별인부 | C7: 197450 | D7: 1034 | E7: 줄눈공 | F7: 185459 | G7: **1065 | H7: 플랜트보온공 | I7: - | J7: **3003 | K7: 한식목공 | L7: -
A8: 1004 | B8: 조력공 | C8: 165635 | D8: 1035 | E8: 판넬조립공 | F8: 213197 | G8: *1066 | H8: 제철축로공 | I8: 292571 | J8: **3004 | K8: 한식목공조공 | L8: -
A9: *1005 | B9: 제도사 | C9: 209231 | D9: *1036 | E9: 지붕잇기공 | F9: 209602 | G9: 1067 | H9: 비파괴시험공 | I9: 224819 | J9: *3005 | K9: 한식석공 | L9: 303187
A10: 1006 | B10: 비계공 | C10: 278151 | D10: *1037 | E10: 벌목부 | F10: 224390 | G10: **1068 | H10: 특급품질관리원 | I10: - | J10: **3006 | K10: 한식미장공 | L10: -
A11: 1007 | B11: 형틀목공 | C11: 259126 | D11: 1038 | E11: 조경공 | F11: 203631 | G11: *1069 | H11: 고급품질관리원 | I11: 186338 | J11: *3007 | K11: 한식와공 | L11: 322581
A12: 1008 | B12: 철근공 | C12: 252113 | D12: 1039 | E12: 배관공 | F12: 214118 | G12: *1070 | H12: 중급품질관리원 | I12: 166550 | J12: **3008 | K12: 한식와공조공 | L12: -
A13: 1009 | B13: 철공 | C13: 223124 | D13: 1040 | E13: 배관공(수도) | F13: 226771 | G13: *1071 | H13: 초급품질관리원 | I13: 139859 | J13: **3009 | K13: 목조각공 | L13: -
A14: *1010 | B14: 철판공 | C14: 202901 | D14: *1041 | E14: 보일러공 | F14: 210465 | G14: 1072 | H14: 지적기사 | I14: 246481 | J14: **3010 | K14: 석조각공 | L14: -
A15: 1011 | B15: 철골공 | C15: 230145 | D15: 1042 | E15: 위생공 | F15: 202504 | G15: 1073 | H15: 지적산업기사 | I15: 215026 | J15: **3011 | K15: 특수화공 | L15: -
A16: 1012 | B16: 용접공 | C16: 249748 | D16: 1043 | E16: 덕트공 | F16: 198718 | G16: 1074 | H16: 지적기능사 | I16: 188071 | J16: **3012 | K16: 화공 | L16: -
A17: 1013 | B17: 콘크리트공 | C17: 245223 | D17: 1044 | E17: 보온공 | F17: 194048 | G17: 1075 | H17: 내선전공 | I17: 265406 | J17: **3013 | K17: 드잡이공편수 | L17: -
A18: 1014 | B18: 보링공 | C18: 212226 | D18: *1045 | E18: 인력운반공 | F18: 170594 | G18: 1076 | H18: 특고압케이블전공 | I18: 420571 | J18: **3014 | K18: 한식미장공편수 | L18: 325333
A19: 1015 | B19: 착암공 | C19: 194463 | D19: 1046 | E19: 궤도공 | F19: 190168 | G19: 1077 | H19: 고압케이블전공 | I19: 353395 | J19: **3015 | K19: 한식와공편수 | L19: -
A20: 1016 | B20: 화약취급공 | C20: 236187 | D20: *1047 | E20: 건설기계조장 | F20: 186691 | G20: 1078 | H20: 저압케이블전공 | I20: 288442 | J20: **3016 | K20: 한식단청공편수 | L20: -
A21: 1017 | B21: 할석공 | C21: 210767 | D21: 1048 | E21: 건설기계운전사 | F21: 243295 | G21: 1079 | H21: 송전전공 | I21: 536946 | J21: *3017 | K21: 한식석공조공 | L21: 308571
A22: *1018 | B22: 포설공 | C22: 194853 | D22: 1049 | E22: 화물차운전사 | F22: 208927 | G22: 1080 | H22: 송전활선전공 | I22: 590847 | J22: **3018 | K22: 한식미장공조공 | L22: -
A23: 1019 | B23: 포장공 | C23: 237245 | D23: **1050 | E23: 일반기계운전사 | F23: - | G23: 1081 | H23: 배전전공 | I23: 397259 | J23: 4001 | K23: 원자력플랜트전공 | L23: 228504
A24: *1020 | B24: 잠수부 | C24: 346760 | D24: 1051 | E24: 기계설비공 | F24: 213337 | G24: 1082 | H24: 배전활선전공 | I24: 520394 | J24: 4002 | K24: 원자력용접공 | L24: 197956
A25: 1021 | B25: 조적공 | C25: 242636 | D25: *1052 | E25: 준설선선장 | F25: 209438 | G25: 1083 | H25: 플랜트전공 | I25: 251195 | J25: 4003 | K25: 원자력기계설치공 | L25: 228419
A26: 1022 | B26: 견출공 | C26: 232725 | D26: *1053 | E26: 준설선기관사 | F26: 184956 | G26: 1084 | H26: 계장공 | I26: 283405 | J26: 4004 | K26: 원자력품질관리사 | L26: 281198
A27: 1023 | B27: 건축목공 | C27: 254714 | D27: *1054 | E27: 준설선운전사 | F27: 180381 | G27: 1085 | H27: 철도신호공 | I27: 271097 | J27: 5001 | K27: 통신관련기사 | L27: 292454
A28: 1024 | B28: 창호공 | C28: 236675 | D28: *1055 | E28: 선원 | F28: 175538 | G28: 1086 | H28: 통신내선공 | I28: 251790 | J28: 5002 | K28: 통신관련산업기사 | L28: 284281
A29: 1025 | B29: 유리공 | C29: 235191 | D29: 1056 | E29: 플랜트배관공 | F29: 296392 | G29: 1087 | H29: 통신설비공 | I29: 280506 | J29: 5003 | K29: 통신관련기능사 | L29: 234222
A30: 1026 | B30: 방수공 | C30: 199427 | D30: 1057 | E30: 플랜트제관공 | F30: 236086 | G30: 1088 | H30: 통신외선공 | I30: 363102 | J30: 5004 | K30: 전기공사기사 | L30: 299140
A31: 1027 | B31: 미장공 | C31: 251976 | D31: 1058 | E31: 플랜트용접공 | F31: 273303 | G31: 1089 | H31: 통신케이블공 | I31: 389536 | J31: 5005 | K31: 전기공사산업기사 | L31: 265465
A32: 1028 | B32: 타일공 | C32: 258576 | D32: **1059 | E32: 플랜트특수용접공 | F32: - | G32: 1090 | H32: 무선안테나공 | I32: 319190 | J32: 5006 | K32: 변전전공 | L32: 437936
A33: 1029 | B33: 도장공 | C33: 242035 | D33: 1060 | E33: 플랜트기계설치공 | F33: 240797 | G33: *1091 | H33: 석면해체공 | I33: 198675 | J33: 5007 | K33: 코킹공 | L33: 194831
A34: 1030 | B34: 내장공 | C34: 228883 | D34: 1061 | E34: 플랜트특별인부 | F34: 205095 | G34: 2001 | H34: 광케이블설치사 | I34: 409726 | J34: 5008 | K34: 특급품질관리기술인 | L34: 266470
A35: 1031 | B35: 도배공 | C35: 205156 | D35: 1062 | E35: 플랜트케이블전공 | F35: 290265 | G35: 2002 | H35: H/W시험사 | I35: 354947 | J35: 5009 | K35: 고급품질관리기술인 | L35: 216510
G36: 2003 | H36: S/W시험사 | I36: 401195 | J36: *5010 | K36: 중급품질관리기술인 | L36: 183604
J37: 5011 | K37: 초급품질관리기술인 | L37: 158227

Sheet 관급집계표
A1: ='표지 '!A5:M5 -> 순천 향교 CCTV 구매 설치 | K1: [ 관 급 집 계 표 ]
A2: 연번 | B2: 품 명 | C2: 규 격 | D2: 단위 | E2: 수량 | F2: 재료비 | H2: 노무비 | K2: 계 | L2: 비고
F3: 단가 | G3: 금액 | H3: 단가 | I3: 금액 | J3: 단가
A4: 1 | B4: =A1 -> 순천 향교 CCTV 구매 설치 | D4: 식 | E4: 1 | G4: =관급내역서!L19 -> 20174460 | K4: =G4 -> 20174460
B5: 조달수수료 | D5: % | E5: 0.54 | G5: =관급내역서!L20 -> 108942.08 | K5: =G5 -> 108942.08
B6: 소 계 | G6: =ROUNDUP(SUM(G4:G5),-3) -> 20284000 | K6: =G6 -> 20284000 | L6: 백단위 절상
B23: 총 계 | G23: =G6 -> 20284000 | K23: =G23 -> 20284000 | L23: 백단위 절상

Sheet 관급내역서
A1: ='표지 '!A5:M5 -> 순천 향교 CCTV 구매 설치 | L1: [ 관 급 내 역 서 ]
A2: 연번 | B2: 품 명 | C2: 규 격 | D2: 단위 | E2: 수량 | F2: 재료비 | H2: 노무비 | J2: 경비 | L2: 계 | M2: G2B식별번호 | N2: 계약방법 | O2: 인도조건 | P2: 납품기한 | Q2: 하자보수기간 | R2: 계약종료일
F3: 단가 | G3: 금액 | H3: 단가 | I3: 금액 | J3: 단가 | K3: 금액
A4: =수량산출서!A7 -> 1 | B4: =수량산출서!B7 -> 순천 향교 CCTV 구매 설치[관급자재] | U4: 업체명 | V4: 구매처
A5: =수량산출서!A8 -> 1-1 | B5: =수량산출서!B8 -> 영상감시장치 | C5: =수량산출서!C8 -> 고정형, 200만화소, 4배줌 | D5: =수량산출서!D8 -> 조 | E5: =수량산출서!E8 -> 1 | F5: =단가조사!E5 -> 3281000 | G5: =E5*F5 -> 3281000 | L5: =G5 -> 3281000 | M5: =수량산출서!J8 -> 본품 25454886 | N5: 3자단가계약 | O5: 현장설치도 | P5: 90일 | Q5: 2년 | R5: 47134 | T5: 본품 | U5: =단가조사!F5 -> 코리아넷 | V5: 나라장터쇼핑몰
A6: =수량산출서!A9 -> 1-2 | B6: =수량산출서!B9 -> 보안용카메라 | C6: =수량산출서!C9 -> 고정형, 200만화소, 4배줌 | D6: =수량산출서!D9 -> 대 | E6: =수량산출서!E9 -> 5 | F6: =단가조사!E6 -> 1487000 | G6: =E6*F6 -> 7435000 | L6: =G6 -> 7435000 | M6: =수량산출서!J9 -> 25454886 옵션 25104211 | N6: 3자단가계약 | O6: 현장설치도 | P6: 90일 | Q6: 2년 | R6: 47134 | T6: 옵션 | U6: =단가조사!F6 -> 코리아넷 | V6: 나라장터쇼핑몰
A7: =수량산출서!A10 -> 1-3 | B7: =수량산출서!B10 -> 디지털비디오레코더 | C7: =수량산출서!C10 -> 16ch | D7: =수량산출서!D10 -> 대 | E7: =수량산출서!E10 -> 1 | F7: =단가조사!E7 -> 5431000 | G7: =E7*F7 -> 5431000 | L7: =G7 -> 5431000 | M7: =수량산출서!J10 -> 25454886 옵션 25560063 | N7: 3자단가계약 | O7: 현장설치도 | P7: 90일 | Q7: 2년 | R7: 47134 | T7: 옵션 | U7: =단가조사!F7 -> 코리아넷 | V7: 나라장터쇼핑몰
A8: =수량산출서!A11 -> 1-4 | B8: =수량산출서!B11 -> 네트워크스위치 | C8: =수량산출서!C11 -> 24port PoE | D8: =수량산출서!D11 -> 대 | E8: =수량산출서!E11 -> 1 | F8: =단가조사!E8 -> 1552000 | G8: =E8*F8 -> 1552000 | L8: =G8 -> 1552000 | M8: =수량산출서!J11 -> 25454886 옵션 25527067 | N8: 3자단가계약 | O8: 현장설치도 | P8: 90일 | Q8: 2년 | R8: 47134 | T8: 옵션 | U8: =단가조사!F8 -> 코리아넷 | V8: 나라장터쇼핑몰
A9: =수량산출서!A12 -> 1-5 | B9: =수량산출서!B12 -> 네트워크스위치 | C9: =수량산출서!C12 -> 8port PoE | D9: =수량산출서!D12 -> 대 | E9: =수량산출서!E12 -> 1 | F9: =단가조사!E9 -> 295000 | G9: =E9*F9 -> 295000 | L9: =G9 -> 295000 | M9: =수량산출서!J12 -> 25454886 옵션 22943457 | N9: 3자단가계약 | O9: 현장설치도 | P9: 90일 | Q9: 2년 | R9: 47134 | T9: 옵션 | U9: =단가조사!F9 -> 코리아넷 | V9: 나라장터쇼핑몰
A10: =수량산출서!A13 -> 1-6 | B10: =수량산출서!B13 -> 하드디스크드라이브 | C10: =수량산출서!C13 -> 6TB | D10: =수량산출서!D13 -> 개 | E10: =수량산출서!E13 -> 2 | F10: =단가조사!E10 -> 392000 | G10: =E10*F10 -> 784000 | L10: =G10 -> 784000 | M10: =수량산출서!J13 -> 25454886 옵션 24432409 | N10: 3자단가계약 | O10: 현장설치도 | P10: 90일 | Q10: 2년 | R10: 47134 | T10: 옵션 | U10: =단가조사!F10 -> 코리아넷 | V10: 나라장터쇼핑몰
A11: =수량산출서!A14 -> 1-7 | B11: =수량산출서!B14 -> 난연전력케이블 | C11: =수량산출서!C14 -> F-CV 3C×2.5㎟ | D11: =수량산출서!D14 -> M | E11: =수량산출서!E14 -> 80 | F11: =단가조사!E11 -> 4600 | G11: =E11*F11 -> 368000 | L11: =G11 -> 368000 | M11: =수량산출서!J14 -> 24978887 옵션 22067190 | N11: 다수공급자계약 | O11: 현장설치도 | P11: 60일 | Q11: 2년 | R11: 46284 | T11: 옵션 | U11: =단가조사!F11 -> 코리아넷 | V11: 나라장터쇼핑몰
A12: =수량산출서!A15 -> 1-8 | B12: =수량산출서!B15 -> UTP케이블 | C12: =수량산출서!C15 -> CAT.5E/CM 4P | D12: =수량산출서!D15 -> M | E12: =수량산출서!E15 -> 135 | F12: =단가조사!E12 -> 2740 | G12: =E12*F12 -> 369900 | L12: =G12 -> 369900 | M12: =수량산출서!J15 -> 24978887 옵션 22067194 | N12: 다수공급자계약 | O12: 현장설치도 | P12: 60일 | Q12: 2년 | R12: 46284 | T12: 옵션 | U12: =단가조사!F12 -> 코리아넷 | V12: 나라장터쇼핑몰
A13: =수량산출서!A16 -> 1-9 | B13: =수량산출서!B16 -> 정보통신공사 | C13: =수량산출서!C16 -> 종합시험 | D13: =수량산출서!D16 -> 식 | E13: =수량산출서!E16 -> 6 | F13: =단가조사!E13 -> 109760 | G13: =E13*F13 -> 658560 | L13: =G13 -> 658560 | M13: =수량산출서!J16 -> 24978887 옵션 22066421 | N13: 다수공급자계약 | O13: 현장설치도 | P13: 60일 | Q13: 2년 | R13: 46284 | T13: 옵션 | U13: =단가조사!F13 -> 코리아넷 | V13: 나라장터쇼핑몰
B19: 소 계 | L19: =SUM(L5:L17) -> 20174460
B20: 조달수수료 | C20: 0.0054 | D20: % | E20: 0.54 | L20: =L19*0.0054 -> 108942.08
B21: 합 계 | L21: =ROUNDUP(SUM(L19:L20),-3) -> 20284000

Sheet 수량산출서
A1: ='표지 '!A5:M5 -> 순천 향교 CCTV 구매 설치
A2: 연번 | B2: 품 명 | C2: 규 격 | D2: 단위 | E2: 수량 | F2: 전교실_서재 | G2: 명륜당_정문 | H2: 후문 | I2: 대성전 | J2: 비고
B4: 공사 유형(신규) | F4: 신규 | G4: 신규 | H4: 신규 | I4: 신규
B5: 카메라 유형 | C5: 합계 | D5: EA | E5: =SUM(F5:I5) -> 6 | F5: =SUM(F6:F6) -> 1 | G5: =SUM(G6:G6) -> 1 | H5: =SUM(H6:H6) -> 1 | I5: =SUM(I6:I6) -> 3
C6: 고정형 | D6: EA | E6: =SUM(F6:I6) -> 6 | F6: 1 | G6: 1 | H6: 1 | I6: 3
A7: 1 | B7: =A1&"[관급자재]" -> 순천 향교 CCTV 구매 설치[관급자재] | D7: 식 | E7: 1
A8: 1-1 | B8: 영상감시장치 | C8: 고정형, 200만화소, 4배줌 | D8: 조 | E8: =SUM(F8:I8) -> 1 | F8: 1 | J8: =K8&" "&단가조사!H5 -> 본품 25454886 | K8: 본품
A9: 1-2 | B9: 보안용카메라 | C9: 고정형, 200만화소, 4배줌 | D9: 대 | E9: =SUM(F9:I9) -> 5 | G9: 1 | H9: 1 | I9: 3 | J9: =K9&" "&단가조사!H6 -> 25454886 옵션 25104211 | K9: 25454886 옵션
A10: 1-3 | B10: 디지털비디오레코더 | C10: 16ch | D10: 대 | E10: =SUM(F10:I10) -> 1 | F10: 1 | J10: =K10&" "&단가조사!H7 -> 25454886 옵션 25560063 | K10: 25454886 옵션
A11: 1-4 | B11: 네트워크스위치 | C11: 24port PoE | D11: 대 | E11: =SUM(F11:I11) -> 1 | F11: 1 | J11: =K11&" "&단가조사!H8 -> 25454886 옵션 25527067 | K11: 25454886 옵션
A12: 1-5 | B12: 네트워크스위치 | C12: 8port PoE | D12: 대 | E12: =SUM(F12:I12) -> 1 | I12: 1 | J12: =K12&" "&단가조사!H9 -> 25454886 옵션 22943457 | K12: 25454886 옵션
A13: 1-6 | B13: 하드디스크드라이브 | C13: 6TB | D13: 개 | E13: =SUM(F13:I13) -> 2 | F13: 2 | J13: =K13&" "&단가조사!H10 -> 25454886 옵션 24432409 | K13: 25454886 옵션
A14: 1-7 | B14: 난연전력케이블 | C14: F-CV 3C×2.5㎟ | D14: M | E14: =SUM(F14:I14) -> 80 | G14: 5 | H14: 5 | I14: 70 | J14: =K14&" "&단가조사!H11 -> 24978887 옵션 22067190 | K14: 24978887 옵션
A15: 1-8 | B15: UTP케이블 | C15: CAT.5E/CM 4P | D15: M | E15: =SUM(F15:I15) -> 135 | F15: 25 | G15: 20 | H15: 15 | I15: 75 | J15: =K15&" "&단가조사!H12 -> 24978887 옵션 22067194 | K15: 24978887 옵션
A16: 1-9 | B16: 정보통신공사 | C16: 종합시험 | D16: 식 | E16: =SUM(F16:I16) -> 6 | F16: 1 | G16: 1 | H16: 1 | I16: 3 | J16: =K16&" "&단가조사!H13 -> 24978887 옵션 22066421 | K16: 24978887 옵션

Sheet 단가조사
A1: ='표지 '!A5:M5 -> 순천 향교 CCTV 구매 설치 | Q1: [ 관 급 단 가 조 사 ]
A2: 연번 | B2: 품 명 | C2: 규 격 | D2: 단위 | E2: 적용단가 | F2: 적용회사(A사) | J2: B사 | N2: C사 | R2: 비 고
F3: 적용회사 | G3: 규격 | H3: 물품식별번호 | I3: 단가 | J3: 회사명 | K3: 규격 | L3: 물품식별번호 | M3: 단가 | N3: 회사명 | O3: 규격 | P3: 물품식별번호 | Q3: 단가
A4: =수량산출서!A7 -> 1 | B4: =A1&"[관급자재]" -> 순천 향교 CCTV 구매 설치[관급자재]
A5: =수량산출서!A8 -> 1-1 | B5: =수량산출서!B8 -> 영상감시장치 | C5: =수량산출서!C8 -> 고정형, 200만화소, 4배줌 | D5: =수량산출서!D8 -> 조 | E5: =MIN(I5,M5,Q5) -> 3281000 | F5: 코리아넷 | G5: =수량산출서!C8 -> 고정형, 200만화소, 4배줌 | H5: 25454886 | I5: 3281000 | J5: 인텔리빅스 | K5: =G5 -> 고정형, 200만화소, 4배줌 | L5: 25844997 | M5: 3425000 | N5: 에스카 | O5: =K5 -> 고정형, 200만화소, 4배줌 | P5: 25205029 | Q5: 3370000 | R5: 현장설치도
A6: =수량산출서!A9 -> 1-2 | B6: =수량산출서!B9 -> 보안용카메라 | C6: =수량산출서!C9 -> 고정형, 200만화소, 4배줌 | D6: =수량산출서!D9 -> 대 | E6: =MIN(I6,M6,Q6) -> 1487000 | F6: 코리아넷 | G6: =수량산출서!C9 -> 고정형, 200만화소, 4배줌 | H6: 25104211 | I6: 1487000 | J6: 인텔리빅스 | K6: =G6 -> 고정형, 200만화소, 4배줌 | L6: 24194252 | M6: 1620000 | N6: 에스카 | O6: =G6 -> 고정형, 200만화소, 4배줌 | P6: 24479041 | Q6: 1516000 | R6: 현장설치도
A7: =수량산출서!A10 -> 1-3 | B7: =수량산출서!B10 -> 디지털비디오레코더 | C7: =수량산출서!C10 -> 16ch | D7: =수량산출서!D10 -> 대 | E7: =MIN(I7,M7,Q7) -> 5431000 | F7: 코리아넷 | G7: =수량산출서!C10 -> 16ch | H7: 25560063 | I7: 5431000 | J7: 시큐인포 | K7: =G7 -> 16ch | L7: 23221272 | M7: 5624000 | N7: 에스카 | O7: =G7 -> 16ch | P7: 25560063 | Q7: 6036000 | R7: 현장설치도
A8: =수량산출서!A11 -> 1-4 | B8: =수량산출서!B11 -> 네트워크스위치 | C8: =수량산출서!C11 -> 24port PoE | D8: =수량산출서!D11 -> 대 | E8: =MIN(I8,M8,Q8) -> 1552000 | F8: 코리아넷 | G8: =수량산출서!C11 -> 24port PoE | H8: 25527067 | I8: 1552000 | J8: 인텔리빅스 | K8: =G8 -> 24port PoE | L8: 25527067 | M8: 1693000 | N8: 에스카 | O8: =G8 -> 24port PoE | P8: 25527067 | Q8: 1696000 | R8: 현장설치도
A9: =수량산출서!A12 -> 1-5 | B9: =수량산출서!B12 -> 네트워크스위치 | C9: =수량산출서!C12 -> 8port PoE | D9: =수량산출서!D12 -> 대 | E9: =MIN(I9,M9,Q9) -> 295000 | F9: 코리아넷 | G9: =수량산출서!C12 -> 8port PoE | H9: 22943457 | I9: 295000 | J9: 인텔리빅스 | K9: =G9 -> 8port PoE | L9: 23641018 | M9: 504000 | N9: 에스카 | O9: =G9 -> 8port PoE | P9: 23578440 | Q9: 529000 | R9: 현장설치도
A10: =수량산출서!A13 -> 1-6 | B10: =수량산출서!B13 -> 하드디스크드라이브 | C10: =수량산출서!C13 -> 6TB | D10: =수량산출서!D13 -> 개 | E10: =MIN(I10,M10,Q10) -> 392000 | F10: 코리아넷 | G10: =수량산출서!C13 -> 6TB | H10: 24432409 | I10: 392000 | J10: 시큐인포 | K10: =G10 -> 6TB | L10: 24172505 | M10: 570000 | N10: 에스카 | O10: =G10 -> 6TB | P10: 25534746 | Q10: 770000 | R10: 현장설치도
A11: =수량산출서!A14 -> 1-7 | B11: =수량산출서!B14 -> 난연전력케이블 | C11: =수량산출서!C14 -> F-CV 3C×2.5㎟ | D11: =수량산출서!D14 -> M | E11: =MIN(I11,M11,Q11) -> 4600 | F11: 코리아넷 | G11: =수량산출서!C14 -> F-CV 3C×2.5㎟ | H11: 22067190 | I11: 4600 | J11: 인텔리빅스 | K11: =G11 -> F-CV 3C×2.5㎟ | L11: =H11 -> 22067190 | M11: =I11 -> 4600 | N11: 에스카 | O11: =K11 -> F-CV 3C×2.5㎟ | P11: =L11 -> 22067190 | Q11: =M11 -> 4600 | R11: 현장설치도
A12: =수량산출서!A15 -> 1-8 | B12: =수량산출서!B15 -> UTP케이블 | C12: =수량산출서!C15 -> CAT.5E/CM 4P | D12: =수량산출서!D15 -> M | E12: =MIN(I12,M12,Q12) -> 2740 | F12: 코리아넷 | G12: =수량산출서!C15 -> CAT.5E/CM 4P | H12: 22067194 | I12: 2740 | J12: 인텔리빅스 | K12: =G12 -> CAT.5E/CM 4P | L12: =H12 -> 22067194 | M12: =I12 -> 2740 | N12: 에스카 | O12: =K12 -> CAT.5E/CM 4P | P12: =L12 -> 22067194 | Q12: =M12 -> 2740 | R12: 현장설치도
A13: =수량산출서!A16 -> 1-9 | B13: =수량산출서!B16 -> 정보통신공사 | C13: =수량산출서!C16 -> 종합시험 | D13: =수량산출서!D16 -> 식 | E13: =MIN(I13,M13,Q13) -> 109760 | F13: 코리아넷 | G13: =수량산출서!C16 -> 종합시험 | H13: 22066421 | I13: 109760 | J13: 인텔리빅스 | K13: =G13 -> 종합시험 | L13: =H13 -> 22066421 | M13: =I13 -> 109760 | N13: 에스카 | O13: =K13 -> 종합시험 | P13: =L13 -> 22066421 | Q13: =M13 -> 109760 | R13: 현장설치도
I26: 323000

Sheet 물가정보

Sheet 조달물품
B1: 순천 향교 CCTV 구매 설치 [조달물품]
A3: 1-1 | B3: =단가조사!B5 -> 영상감시장치 | C3: 물품식별번호 : | D3: =단가조사!H5 -> 25454886 | E3: 제조사 : | F3: =단가조사!F5 -> 코리아넷 | G3: 수량 | H3: 비교1 | I3: 물품식별번호 : | J3: =단가조사!L5 -> 25844997 | K3: 제조사 : | L3: =단가조사!J5 -> 인텔리빅스 | M3: 비교2 | N3: 물품식별번호 : | O3: =단가조사!P5 -> 25205029 | P3: 제조사 : | Q3: =단가조사!N5 -> 에스카
G4: =수량산출서!E8 -> 1
A5: 1-2 | B5: =단가조사!B6 -> 보안용카메라 | C5: 물품식별번호 : | D5: =단가조사!H6 -> 25104211 | E5: 제조사 : | F5: =단가조사!F6 -> 코리아넷 | G5: 수량 | H5: 비교1 | I5: 물품식별번호 : | J5: =단가조사!L6 -> 24194252 | K5: 제조사 : | L5: =단가조사!J6 -> 인텔리빅스 | M5: 비교2 | N5: 물품식별번호 : | O5: =단가조사!P6 -> 24479041 | P5: 제조사 : | Q5: =단가조사!N6 -> 에스카
G6: =수량산출서!E9 -> 5
A7: 1-3 | B7: =단가조사!B7 -> 디지털비디오레코더 | C7: 물품식별번호 : | D7: =단가조사!H7 -> 25560063 | E7: 제조사 : | F7: =단가조사!F7 -> 코리아넷 | H7: 비교1 | I7: 물품식별번호 : | J7: =단가조사!L7 -> 23221272 | K7: 제조사 : | L7: =단가조사!J7 -> 시큐인포 | M7: 비교2 | N7: 물품식별번호 : | O7: =단가조사!P7 -> 25560063 | P7: 제조사 : | Q7: =단가조사!N7 -> 에스카
G8: =수량산출서!E10 -> 1
A9: 1-4 | B9: =단가조사!B8 -> 네트워크스위치 | C9: 물품식별번호 : | D9: =단가조사!H8 -> 25527067 | E9: 제조사 : | F9: =단가조사!F8 -> 코리아넷 | G9: 수량 | H9: 비교1 | I9: 물품식별번호 : | J9: =단가조사!L8 -> 25527067 | K9: 제조사 : | L9: =단가조사!J8 -> 인텔리빅스 | M9: 비교2 | N9: 물품식별번호 : | O9: =단가조사!P8 -> 25527067 | P9: 제조사 : | Q9: =단가조사!N8 -> 에스카
G10: =수량산출서!E11 -> 1
A11: 1-5 | B11: =단가조사!B9 -> 네트워크스위치 | C11: 물품식별번호 : | D11: =단가조사!H9 -> 22943457 | E11: 제조사 : | F11: =단가조사!F9 -> 코리아넷 | G11: 수량 | H11: 비교1 | I11: 물품식별번호 : | J11: =단가조사!L9 -> 23641018 | K11: 제조사 : | L11: =단가조사!J9 -> 인텔리빅스 | M11: 비교2 | N11: 물품식별번호 : | O11: =단가조사!P9 -> 23578440 | P11: 제조사 : | Q11: =단가조사!N9 -> 에스카
G12: =수량산출서!E12 -> 1
A13: 1-6 | B13: =단가조사!B10 -> 하드디스크드라이브 | C13: 물품식별번호 : | D13: =단가조사!H10 -> 24432409 | E13: 제조사 : | F13: =단가조사!F10 -> 코리아넷 | G13: 수량 | H13: 비교1 | I13: 물품식별번호 : | J13: =단가조사!L10 -> 24172505 | K13: 제조사 : | L13: =단가조사!J10 -> 시큐인포 | M13: 비교2 | N13: 물품식별번호 : | O13: =단가조사!P10 -> 25534746 | P13: 제조사 : | Q13: =단가조사!N10 -> 에스카
G14: =수량산출서!E13 -> 2
A15: 1-7 | B15: =단가조사!B11 -> 난연전력케이블 | C15: 물품식별번호 : | D15: =단가조사!H11 -> 22067190 | E15: 제조사 : | F15: =단가조사!F11 -> 코리아넷 | G15: 수량 | H15: 비교1 | I15: 물품식별번호 : | J15: =단가조사!L11 -> 22067190 | K15: 제조사 : | L15: =단가조사!J11 -> 인텔리빅스 | M15: 비교2 | N15: 물품식별번호 : | O15: =단가조사!P11 -> 22067190 | P15: 제조사 : | Q15: =단가조사!N11 -> 에스카
G16: =수량산출서!E14 -> 80
A17: 1-8 | B17: =단가조사!B12 -> UTP케이블 | C17: 물품식별번호 : | D17: =단가조사!H12 -> 22067194 | E17: 제조사 : | F17: =단가조사!F12 -> 코리아넷 | G17: 수량 | H17: 비교1 | I17: 물품식별번호 : | J17: =단가조사!L12 -> 22067194 | K17: 제조사 : | L17: =단가조사!J12 -> 인텔리빅스 | M17: 비교2 | N17: 물품식별번호 : | O17: =단가조사!P12 -> 22067194 | P17: 제조사 : | Q17: =단가조사!N12 -> 에스카
G18: =수량산출서!E15 -> 135
A19: 1-9 | B19: =단가조사!B13 -> 정보통신공사 | C19: 물품식별번호 : | D19: =단가조사!H13 -> 22066421 | E19: 제조사 : | F19: =단가조사!F13 -> 코리아넷 | G19: 수량 | H19: 비교1 | I19: 물품식별번호 : | J19: =단가조사!L13 -> 22066421 | K19: 제조사 : | L19: =단가조사!J13 -> 인텔리빅스 | M19: 비교2 | N19: 물품식별번호 : | O19: =단가조사!P13 -> 22066421 | P19: 제조사 : | Q19: =단가조사!N13 -> 에스카
G20: =수량산출서!E16 -> 6

Sheet 설치 구성도

Sheet 공정표
A1: 예 정 공 정 표
A2: ='표지 '!A5:M5 -> 순천 향교 CCTV 구매 설치
A3: 일 정 공정별 | B3: 착수일로부터 60일
B4: 1~5일 | D4: 6~15일 | F4: 16~50일 | H4: 51~55일 | I4: 56~60일
A5: 1. 착수 및 자재 검토
A6: 2. 현장조사 및 자재 준비
A7: 3. 카메라, 시스템 설치
A8: 4. 전기 및 선로 구축
A9: 5. 관제센터 연계, 시운전 및 종합시험
A10: 6. 교육 및 인수인계, 완료

Sheet 견적서
B2: 견 적 서
B4: 순천시청 | E4: 귀중 | H4: ㈜ 코 리 아 넷
G5: 사업자등록번호 : 416-81-21437
B6: 견 적 일 : 2022년 12월 | G6: 대 표 : 채 강 석 (인)
B7: 건 명 : 자재단가요구서 | G7: 전남 순천시 해룡면 해룡산단5로 57
G8: TEL : (061)744-6266/ FAX: 744-6268
B10: ="합계금액 : 일금"&NUMBERSTRING(H36,1)&"원정 (\"&TEXT(H36,"#,###")&")" -> #REF!
B12: 아래와 같이 견적합니다 | I12: 담당자 정문영이사 010-7553-5000
B14: 번호 | C14: 품 명 | D14: 규 격 | E14: 단 위 | F14: 수 량 | G14: 단 가 | H14: 금 액 | I14: 비 고
B15: 1
B16: 1 | C16: =수량산출서!#REF! -> #REF! | D16: =수량산출서!#REF! -> #REF! | E16: =수량산출서!#REF! -> #REF! | F16: =수량산출서!#REF! -> #REF! | G16: =단가조사!#REF! -> #REF! | H16: =G16*F16 -> #REF!
B17: 2 | C17: =수량산출서!#REF! -> #REF! | D17: =수량산출서!#REF! -> #REF! | E17: =수량산출서!#REF! -> #REF! | F17: =수량산출서!#REF! -> #REF! | G17: =단가조사!#REF! -> #REF! | H17: =G17*F17 -> #REF!
B18: 3 | C18: =수량산출서!#REF! -> #REF! | D18: =수량산출서!#REF! -> #REF! | E18: =수량산출서!#REF! -> #REF! | F18: =수량산출서!#REF! -> #REF! | G18: =단가조사!#REF! -> #REF! | H18: =G18*F18 -> #REF!
B19: 4 | C19: =수량산출서!#REF! -> #REF! | D19: =수량산출서!#REF! -> #REF! | E19: =수량산출서!#REF! -> #REF! | F19: =수량산출서!#REF! -> #REF! | G19: =단가조사!#REF! -> #REF! | H19: =G19*F19 -> #REF!
B20: 5 | C20: =수량산출서!#REF! -> #REF! | D20: =수량산출서!#REF! -> #REF! | E20: =수량산출서!#REF! -> #REF! | F20: =수량산출서!#REF! -> #REF! | G20: =단가조사!#REF! -> #REF! | H20: =G20*F20 -> #REF!
B21: 6
B22: 7
B23: 8
B24: 9
F34: 합 계 | H34: =SUM(H16:H32) -> #REF!
F35: V A T | H35: =H34/10 -> #REF!
F36: 총 계 | H36: =SUM(H34+H35) -> #REF!
B37: ■ SI(통합관제). CCTV. AV시스템. 통신공사. 유지보수. 통합배선반. 보안시스템. 엔지니어링 ■

Sheet 견적서2
F3: <견 적 서 >
A5: 2022 년 12월 일 | E5: □ 주 소 : 전라남도 순천시 고지4길 11-50(가곡동)
A6: 순천시청 담당자 貴中 | E6: □ E-mail : 1000sucms@hanmail.net
E7: □ T E L : (061)722-1410 / FAX:(061)722-1415
A8: 아래와 같이 계산합니다. | E8: □ 대표이사 : 전 석 (인)
A10: =" 합 계 : 一金 "&NUMBERSTRING(F31,1)&" 원정" -> #REF! | E10: =F31 -> #REF!
A12: 품 명 | B12: 규 격 | C12: 단 위 | D12: 수 량 | E12: 단 가 | F12: 견적금액 | G12: 비 고
A13: 공사명 : 자재단가요구서
A14: =단가조사!#REF! -> #REF! | B14: =단가조사!#REF! -> #REF! | C14: =단가조사!#REF! -> #REF! | D14: =수량산출서!#REF! -> #REF! | E14: =단가조사!#REF! -> #REF! | F14: =D14*E14 -> #REF!
A15: =단가조사!#REF! -> #REF! | B15: =단가조사!#REF! -> #REF! | C15: =단가조사!#REF! -> #REF! | D15: =수량산출서!#REF! -> #REF! | E15: =단가조사!#REF! -> #REF! | F15: =D15*E15 -> #REF!
A16: =단가조사!#REF! -> #REF! | B16: =단가조사!#REF! -> #REF! | C16: =단가조사!#REF! -> #REF! | D16: =수량산출서!#REF! -> #REF! | E16: =단가조사!#REF! -> #REF! | F16: =D16*E16 -> #REF!
A17: =단가조사!#REF! -> #REF! | B17: =단가조사!#REF! -> #REF! | C17: =단가조사!#REF! -> #REF! | D17: =수량산출서!#REF! -> #REF! | E17: =단가조사!#REF! -> #REF! | F17: =D17*E17 -> #REF!
A18: =단가조사!#REF! -> #REF! | B18: =단가조사!#REF! -> #REF! | C18: =단가조사!#REF! -> #REF! | D18: =수량산출서!#REF! -> #REF! | E18: =단가조사!#REF! -> #REF! | F18: =D18*E18 -> #REF!
A28: 합 계 | F28: =SUM(F14:F27) -> #REF!
A29: 적 용 | F29: =F28 -> #REF!
A30: 부 가 가 치 세 | F30: =F29*10% -> #REF!
A31: 총 계 | F31: =SUM(F29:F30) -> #REF!
A32: ★ 주요업무
A33: - | C33: - | D33: 무선 (영상,데이타,음성) 송수신기 설계,제조,설치
A34: - | C34: - | D34: 출입감시(외곽감시) 시스템 구축
A35: - | C35: - | D35: 구내통신공사
